<robot name="partnet_bdf19a60512b5112aec118775e1a3eb4">
	<link name="base"><inertial><mass value="10" /><inertia ixx="1" ixy="0" ixz="0" iyy="1" iyz="0" izz="1" /></inertial></link>
	<link name="link_0">
		<visual name="outside_frame-12">
			<origin xyz="0 0 0" />
			<geometry>
				<mesh filename="textured_objs/original-29.obj" />
			</geometry>
		</visual>
		<collision>
			<origin xyz="0 0 0" />
			<geometry>
				<mesh filename="textured_objs/original-29.obj" />
			</geometry>
		</collision>
	<inertial><mass value="10" /><inertia ixx="1" ixy="0" ixz="0" iyy="1" iyz="0" izz="1" /></inertial></link>
	<joint name="joint_0" type="fixed">
		<origin rpy="1.570796326794897 0 -1.570796326794897" xyz="0 0 0" />
		<child link="link_0" />
		<parent link="base" />
	</joint>
	<link name="link_1">
		<visual name="movable_part-10">
			<origin xyz="0.2718480576000603 -0.14707143841511927 -0.07412800192832969" />
			<geometry>
				<mesh filename="textured_objs/original-24.obj" />
			</geometry>
		</visual>
		<visual name="movable_part-8">
			<origin xyz="0.2718480576000603 -0.14707143841511927 -0.07412800192832969" />
			<geometry>
				<mesh filename="textured_objs/original-27.obj" />
			</geometry>
		</visual>
		<collision>
			<origin xyz="0.2718480576000603 -0.14707143841511927 -0.07412800192832969" />
			<geometry>
				<mesh filename="textured_objs/original-24.obj" />
			</geometry>
		</collision>
		<collision>
			<origin xyz="0.2718480576000603 -0.14707143841511927 -0.07412800192832969" />
			<geometry>
				<mesh filename="textured_objs/original-27.obj" />
			</geometry>
		</collision>
	<inertial><mass value="10" /><inertia ixx="1" ixy="0" ixz="0" iyy="1" iyz="0" izz="1" /></inertial></link>
	<joint name="joint_1" type="revolute">
		<origin xyz="-0.6421963903449441 -0.7487525767254141 0.0723845451324776" />
		<axis xyz="0 0 1" />
		<child link="link_1" />
		<parent link="link_2" />
		<limit effort="30" lower="0.0" upper="1.5707963267948966" velocity="1.0" />
	</joint>
	<link name="link_2">
		<visual name="surface_board-11">
			<origin xyz="-0.37034833274488377 -0.8958240151405333 -0.0017434567958520795" />
			<geometry>
				<mesh filename="textured_objs/original-1.obj" />
			</geometry>
		</visual>
		<visual name="fixed_part-9">
			<origin xyz="-0.37034833274488377 -0.8958240151405333 -0.0017434567958520795" />
			<geometry>
				<mesh filename="textured_objs/original-23.obj" />
			</geometry>
		</visual>
		<visual name="fixed_part-7">
			<origin xyz="-0.37034833274488377 -0.8958240151405333 -0.0017434567958520795" />
			<geometry>
				<mesh filename="textured_objs/original-26.obj" />
			</geometry>
		</visual>
		<collision>
			<origin xyz="-0.37034833274488377 -0.8958240151405333 -0.0017434567958520795" />
			<geometry>
				<mesh filename="textured_objs/original-1.obj" />
			</geometry>
		</collision>
		<collision>
			<origin xyz="-0.37034833274488377 -0.8958240151405333 -0.0017434567958520795" />
			<geometry>
				<mesh filename="textured_objs/original-23.obj" />
			</geometry>
		</collision>
		<collision>
			<origin xyz="-0.37034833274488377 -0.8958240151405333 -0.0017434567958520795" />
			<geometry>
				<mesh filename="textured_objs/original-26.obj" />
			</geometry>
		</collision>
	<inertial><mass value="10" /><inertia ixx="1" ixy="0" ixz="0" iyy="1" iyz="0" izz="1" /></inertial></link>
	<joint name="joint_2" type="revolute">
		<origin xyz="0.37034833274488377 0.8958240151405333 0.0017434567958520795" />
		<axis xyz="0 0.9999999999999999 0" />
		<child link="link_2" />
		<parent link="link_0" />
		<limit effort="30" lower="0.0" upper="1.5707963267948966" velocity="1.0" />
	</joint>
</robot>