<robot name="partnet_1f131f6f97d53a283b5749d1b87fc99c">
	<link name="base"><inertial><mass value="10" /><inertia ixx="1" ixy="0" ixz="0" iyy="1" iyz="0" izz="1" /></inertial></link>
	<link name="link_0">
		<visual name="outside_frame-1">
			<origin xyz="0 0 0" />
			<geometry>
				<mesh filename="textured_objs/original-2.obj" />
			</geometry>
		</visual>
		<collision>
			<origin xyz="0 0 0" />
			<geometry>
				<mesh filename="textured_objs/original-2.obj" />
			</geometry>
		</collision>
	<inertial><mass value="10" /><inertia ixx="1" ixy="0" ixz="0" iyy="1" iyz="0" izz="1" /></inertial></link>
	<joint name="joint_0" type="fixed">
		<origin rpy="1.570796326794897 0 -1.570796326794897" xyz="0 0 0" />
		<child link="link_0" />
		<parent link="base" />
	</joint>
	<link name="link_1">
		<visual name="fixed_part-10">
			<origin xyz="0.2517535 -0.0969835 0" />
			<geometry>
				<mesh filename="textured_objs/new-0.obj" />
			</geometry>
		</visual>
		<visual name="movable_part-11">
			<origin xyz="0.2517535 -0.0969835 0" />
			<geometry>
				<mesh filename="textured_objs/new-1.obj" />
			</geometry>
		</visual>
		<visual name="fixed_part-12">
			<origin xyz="0.2517535 -0.0969835 0" />
			<geometry>
				<mesh filename="textured_objs/new-3.obj" />
			</geometry>
		</visual>
		<visual name="movable_part-13">
			<origin xyz="0.2517535 -0.0969835 0" />
			<geometry>
				<mesh filename="textured_objs/new-2.obj" />
			</geometry>
		</visual>
		<collision>
			<origin xyz="0.2517535 -0.0969835 0" />
			<geometry>
				<mesh filename="textured_objs/new-0.obj" />
			</geometry>
		</collision>
		<collision>
			<origin xyz="0.2517535 -0.0969835 0" />
			<geometry>
				<mesh filename="textured_objs/new-1.obj" />
			</geometry>
		</collision>
		<collision>
			<origin xyz="0.2517535 -0.0969835 0" />
			<geometry>
				<mesh filename="textured_objs/new-3.obj" />
			</geometry>
		</collision>
		<collision>
			<origin xyz="0.2517535 -0.0969835 0" />
			<geometry>
				<mesh filename="textured_objs/new-2.obj" />
			</geometry>
		</collision>
	<inertial><mass value="10" /><inertia ixx="1" ixy="0" ixz="0" iyy="1" iyz="0" izz="1" /></inertial></link>
	<joint name="joint_1" type="continuous">
		<origin xyz="-0.6001041376946065 -0.7270655 -0.01805896177769635" />
		<axis xyz="0 0 -1" />
		<child link="link_1" />
		<parent link="link_2" />
	</joint>
	<link name="link_2">
		<visual name="hinge-8">
			<origin xyz="-0.34835063769460645 -0.824049 -0.01805896177769635" />
			<geometry>
				<mesh filename="textured_objs/original-16.obj" />
			</geometry>
		</visual>
		<visual name="hinge-8">
			<origin xyz="-0.34835063769460645 -0.824049 -0.01805896177769635" />
			<geometry>
				<mesh filename="textured_objs/original-7.obj" />
			</geometry>
		</visual>
		<visual name="hinge-8">
			<origin xyz="-0.34835063769460645 -0.824049 -0.01805896177769635" />
			<geometry>
				<mesh filename="textured_objs/original-5.obj" />
			</geometry>
		</visual>
		<visual name="hinge-8">
			<origin xyz="-0.34835063769460645 -0.824049 -0.01805896177769635" />
			<geometry>
				<mesh filename="textured_objs/original-6.obj" />
			</geometry>
		</visual>
		<visual name="hinge-8">
			<origin xyz="-0.34835063769460645 -0.824049 -0.01805896177769635" />
			<geometry>
				<mesh filename="textured_objs/original-8.obj" />
			</geometry>
		</visual>
		<visual name="hinge-8">
			<origin xyz="-0.34835063769460645 -0.824049 -0.01805896177769635" />
			<geometry>
				<mesh filename="textured_objs/original-4.obj" />
			</geometry>
		</visual>
		<visual name="hinge-8">
			<origin xyz="-0.34835063769460645 -0.824049 -0.01805896177769635" />
			<geometry>
				<mesh filename="textured_objs/original-18.obj" />
			</geometry>
		</visual>
		<visual name="hinge-8">
			<origin xyz="-0.34835063769460645 -0.824049 -0.01805896177769635" />
			<geometry>
				<mesh filename="textured_objs/original-17.obj" />
			</geometry>
		</visual>
		<visual name="hinge-8">
			<origin xyz="-0.34835063769460645 -0.824049 -0.01805896177769635" />
			<geometry>
				<mesh filename="textured_objs/original-19.obj" />
			</geometry>
		</visual>
		<visual name="hinge-8">
			<origin xyz="-0.34835063769460645 -0.824049 -0.01805896177769635" />
			<geometry>
				<mesh filename="textured_objs/original-15.obj" />
			</geometry>
		</visual>
		<visual name="hinge-8">
			<origin xyz="-0.34835063769460645 -0.824049 -0.01805896177769635" />
			<geometry>
				<mesh filename="textured_objs/original-22.obj" />
			</geometry>
		</visual>
		<visual name="hinge-8">
			<origin xyz="-0.34835063769460645 -0.824049 -0.01805896177769635" />
			<geometry>
				<mesh filename="textured_objs/original-21.obj" />
			</geometry>
		</visual>
		<visual name="hinge-8">
			<origin xyz="-0.34835063769460645 -0.824049 -0.01805896177769635" />
			<geometry>
				<mesh filename="textured_objs/original-25.obj" />
			</geometry>
		</visual>
		<visual name="hinge-8">
			<origin xyz="-0.34835063769460645 -0.824049 -0.01805896177769635" />
			<geometry>
				<mesh filename="textured_objs/original-24.obj" />
			</geometry>
		</visual>
		<visual name="hinge-8">
			<origin xyz="-0.34835063769460645 -0.824049 -0.01805896177769635" />
			<geometry>
				<mesh filename="textured_objs/original-23.obj" />
			</geometry>
		</visual>
		<visual name="surface_board-7">
			<origin xyz="-0.34835063769460645 -0.824049 -0.01805896177769635" />
			<geometry>
				<mesh filename="textured_objs/original-10.obj" />
			</geometry>
		</visual>
		<visual name="other_leaf-15">
			<origin xyz="-0.34835063769460645 -0.824049 -0.01805896177769635" />
			<geometry>
				<mesh filename="textured_objs/original-13.obj" />
			</geometry>
		</visual>
		<visual name="other_leaf-15">
			<origin xyz="-0.34835063769460645 -0.824049 -0.01805896177769635" />
			<geometry>
				<mesh filename="textured_objs/original-1.obj" />
			</geometry>
		</visual>
		<collision>
			<origin xyz="-0.34835063769460645 -0.824049 -0.01805896177769635" />
			<geometry>
				<mesh filename="textured_objs/original-16.obj" />
			</geometry>
		</collision>
		<collision>
			<origin xyz="-0.34835063769460645 -0.824049 -0.01805896177769635" />
			<geometry>
				<mesh filename="textured_objs/original-7.obj" />
			</geometry>
		</collision>
		<collision>
			<origin xyz="-0.34835063769460645 -0.824049 -0.01805896177769635" />
			<geometry>
				<mesh filename="textured_objs/original-5.obj" />
			</geometry>
		</collision>
		<collision>
			<origin xyz="-0.34835063769460645 -0.824049 -0.01805896177769635" />
			<geometry>
				<mesh filename="textured_objs/original-6.obj" />
			</geometry>
		</collision>
		<collision>
			<origin xyz="-0.34835063769460645 -0.824049 -0.01805896177769635" />
			<geometry>
				<mesh filename="textured_objs/original-8.obj" />
			</geometry>
		</collision>
		<collision>
			<origin xyz="-0.34835063769460645 -0.824049 -0.01805896177769635" />
			<geometry>
				<mesh filename="textured_objs/original-4.obj" />
			</geometry>
		</collision>
		<collision>
			<origin xyz="-0.34835063769460645 -0.824049 -0.01805896177769635" />
			<geometry>
				<mesh filename="textured_objs/original-18.obj" />
			</geometry>
		</collision>
		<collision>
			<origin xyz="-0.34835063769460645 -0.824049 -0.01805896177769635" />
			<geometry>
				<mesh filename="textured_objs/original-17.obj" />
			</geometry>
		</collision>
		<collision>
			<origin xyz="-0.34835063769460645 -0.824049 -0.01805896177769635" />
			<geometry>
				<mesh filename="textured_objs/original-19.obj" />
			</geometry>
		</collision>
		<collision>
			<origin xyz="-0.34835063769460645 -0.824049 -0.01805896177769635" />
			<geometry>
				<mesh filename="textured_objs/original-15.obj" />
			</geometry>
		</collision>
		<collision>
			<origin xyz="-0.34835063769460645 -0.824049 -0.01805896177769635" />
			<geometry>
				<mesh filename="textured_objs/original-22.obj" />
			</geometry>
		</collision>
		<collision>
			<origin xyz="-0.34835063769460645 -0.824049 -0.01805896177769635" />
			<geometry>
				<mesh filename="textured_objs/original-21.obj" />
			</geometry>
		</collision>
		<collision>
			<origin xyz="-0.34835063769460645 -0.824049 -0.01805896177769635" />
			<geometry>
				<mesh filename="textured_objs/original-25.obj" />
			</geometry>
		</collision>
		<collision>
			<origin xyz="-0.34835063769460645 -0.824049 -0.01805896177769635" />
			<geometry>
				<mesh filename="textured_objs/original-24.obj" />
			</geometry>
		</collision>
		<collision>
			<origin xyz="-0.34835063769460645 -0.824049 -0.01805896177769635" />
			<geometry>
				<mesh filename="textured_objs/original-23.obj" />
			</geometry>
		</collision>
		<collision>
			<origin xyz="-0.34835063769460645 -0.824049 -0.01805896177769635" />
			<geometry>
				<mesh filename="textured_objs/original-10.obj" />
			</geometry>
		</collision>
		<collision>
			<origin xyz="-0.34835063769460645 -0.824049 -0.01805896177769635" />
			<geometry>
				<mesh filename="textured_objs/original-13.obj" />
			</geometry>
		</collision>
		<collision>
			<origin xyz="-0.34835063769460645 -0.824049 -0.01805896177769635" />
			<geometry>
				<mesh filename="textured_objs/original-1.obj" />
			</geometry>
		</collision>
	<inertial><mass value="10" /><inertia ixx="1" ixy="0" ixz="0" iyy="1" iyz="0" izz="1" /></inertial></link>
	<joint name="joint_2" type="revolute">
		<origin xyz="0.34835063769460645 0.824049 0.01805896177769635" />
		<axis xyz="0 0.9999999999999999 0" />
		<child link="link_2" />
		<parent link="link_0" />
		<limit effort="30" lower="0.0" upper="1.5707963267948966" velocity="1.0" />
	</joint>
</robot>