<robot name="partnet_efa22b97f47a8b3558451d47ce84cde7">
	<link name="base"><inertial><mass value="10" /><inertia ixx="1" ixy="0" ixz="0" iyy="1" iyz="0" izz="1" /></inertial></link>
	<link name="link_0">
		<visual name="switch-1">
			<origin xyz="-0.13821602207966688 0.025505218476348797 -0.36373281829417325" />
			<geometry>
				<mesh filename="textured_objs/original-30.obj" />
			</geometry>
		</visual>
		<collision>
			<origin xyz="-0.13821602207966688 0.025505218476348797 -0.36373281829417325" />
			<geometry>
				<mesh filename="textured_objs/original-30.obj" />
			</geometry>
		</collision>
	<inertial><mass value="10" /><inertia ixx="1" ixy="0" ixz="0" iyy="1" iyz="0" izz="1" /></inertial></link>
	<joint name="joint_0" type="revolute">
		<origin xyz="0.13821602207966688 -0.025505218476348797 0.36373281829417325" />
		<axis xyz="1 0 0" />
		<child link="link_0" />
		<parent link="link_1" />
		<limit effort="30" lower="0.0" upper="0.5235987755982988" velocity="1.0" />
	</joint>
	<link name="link_1">
		<visual name="base_body-2">
			<origin xyz="0 0 0" />
			<geometry>
				<mesh filename="textured_objs/original-29.obj" />
			</geometry>
		</visual>
		<visual name="base_body-2">
			<origin xyz="0 0 0" />
			<geometry>
				<mesh filename="textured_objs/original-21.obj" />
			</geometry>
		</visual>
		<visual name="base_body-2">
			<origin xyz="0 0 0" />
			<geometry>
				<mesh filename="textured_objs/original-28.obj" />
			</geometry>
		</visual>
		<visual name="base_body-2">
			<origin xyz="0 0 0" />
			<geometry>
				<mesh filename="textured_objs/original-22.obj" />
			</geometry>
		</visual>
		<visual name="base_body-2">
			<origin xyz="0 0 0" />
			<geometry>
				<mesh filename="textured_objs/original-26.obj" />
			</geometry>
		</visual>
		<visual name="base_body-2">
			<origin xyz="0 0 0" />
			<geometry>
				<mesh filename="textured_objs/original-3.obj" />
			</geometry>
		</visual>
		<visual name="base_body-2">
			<origin xyz="0 0 0" />
			<geometry>
				<mesh filename="textured_objs/original-2.obj" />
			</geometry>
		</visual>
		<visual name="base_body-2">
			<origin xyz="0 0 0" />
			<geometry>
				<mesh filename="textured_objs/original-8.obj" />
			</geometry>
		</visual>
		<visual name="base_body-2">
			<origin xyz="0 0 0" />
			<geometry>
				<mesh filename="textured_objs/original-9.obj" />
			</geometry>
		</visual>
		<visual name="base_body-2">
			<origin xyz="0 0 0" />
			<geometry>
				<mesh filename="textured_objs/original-5.obj" />
			</geometry>
		</visual>
		<visual name="base_body-2">
			<origin xyz="0 0 0" />
			<geometry>
				<mesh filename="textured_objs/original-6.obj" />
			</geometry>
		</visual>
		<visual name="base_body-2">
			<origin xyz="0 0 0" />
			<geometry>
				<mesh filename="textured_objs/original-15.obj" />
			</geometry>
		</visual>
		<visual name="base_body-2">
			<origin xyz="0 0 0" />
			<geometry>
				<mesh filename="textured_objs/original-23.obj" />
			</geometry>
		</visual>
		<visual name="base_body-2">
			<origin xyz="0 0 0" />
			<geometry>
				<mesh filename="textured_objs/original-11.obj" />
			</geometry>
		</visual>
		<visual name="base_body-2">
			<origin xyz="0 0 0" />
			<geometry>
				<mesh filename="textured_objs/original-18.obj" />
			</geometry>
		</visual>
		<visual name="base_body-2">
			<origin xyz="0 0 0" />
			<geometry>
				<mesh filename="textured_objs/original-25.obj" />
			</geometry>
		</visual>
		<visual name="base_body-2">
			<origin xyz="0 0 0" />
			<geometry>
				<mesh filename="textured_objs/original-17.obj" />
			</geometry>
		</visual>
		<visual name="base_body-2">
			<origin xyz="0 0 0" />
			<geometry>
				<mesh filename="textured_objs/original-12.obj" />
			</geometry>
		</visual>
		<visual name="base_body-2">
			<origin xyz="0 0 0" />
			<geometry>
				<mesh filename="textured_objs/original-24.obj" />
			</geometry>
		</visual>
		<visual name="base_body-2">
			<origin xyz="0 0 0" />
			<geometry>
				<mesh filename="textured_objs/original-20.obj" />
			</geometry>
		</visual>
		<visual name="base_body-2">
			<origin xyz="0 0 0" />
			<geometry>
				<mesh filename="textured_objs/original-14.obj" />
			</geometry>
		</visual>
		<collision>
			<origin xyz="0 0 0" />
			<geometry>
				<mesh filename="textured_objs/original-29.obj" />
			</geometry>
		</collision>
		<collision>
			<origin xyz="0 0 0" />
			<geometry>
				<mesh filename="textured_objs/original-21.obj" />
			</geometry>
		</collision>
		<collision>
			<origin xyz="0 0 0" />
			<geometry>
				<mesh filename="textured_objs/original-28.obj" />
			</geometry>
		</collision>
		<collision>
			<origin xyz="0 0 0" />
			<geometry>
				<mesh filename="textured_objs/original-22.obj" />
			</geometry>
		</collision>
		<collision>
			<origin xyz="0 0 0" />
			<geometry>
				<mesh filename="textured_objs/original-26.obj" />
			</geometry>
		</collision>
		<collision>
			<origin xyz="0 0 0" />
			<geometry>
				<mesh filename="textured_objs/original-3.obj" />
			</geometry>
		</collision>
		<collision>
			<origin xyz="0 0 0" />
			<geometry>
				<mesh filename="textured_objs/original-2.obj" />
			</geometry>
		</collision>
		<collision>
			<origin xyz="0 0 0" />
			<geometry>
				<mesh filename="textured_objs/original-8.obj" />
			</geometry>
		</collision>
		<collision>
			<origin xyz="0 0 0" />
			<geometry>
				<mesh filename="textured_objs/original-9.obj" />
			</geometry>
		</collision>
		<collision>
			<origin xyz="0 0 0" />
			<geometry>
				<mesh filename="textured_objs/original-5.obj" />
			</geometry>
		</collision>
		<collision>
			<origin xyz="0 0 0" />
			<geometry>
				<mesh filename="textured_objs/original-6.obj" />
			</geometry>
		</collision>
		<collision>
			<origin xyz="0 0 0" />
			<geometry>
				<mesh filename="textured_objs/original-15.obj" />
			</geometry>
		</collision>
		<collision>
			<origin xyz="0 0 0" />
			<geometry>
				<mesh filename="textured_objs/original-23.obj" />
			</geometry>
		</collision>
		<collision>
			<origin xyz="0 0 0" />
			<geometry>
				<mesh filename="textured_objs/original-11.obj" />
			</geometry>
		</collision>
		<collision>
			<origin xyz="0 0 0" />
			<geometry>
				<mesh filename="textured_objs/original-18.obj" />
			</geometry>
		</collision>
		<collision>
			<origin xyz="0 0 0" />
			<geometry>
				<mesh filename="textured_objs/original-25.obj" />
			</geometry>
		</collision>
		<collision>
			<origin xyz="0 0 0" />
			<geometry>
				<mesh filename="textured_objs/original-17.obj" />
			</geometry>
		</collision>
		<collision>
			<origin xyz="0 0 0" />
			<geometry>
				<mesh filename="textured_objs/original-12.obj" />
			</geometry>
		</collision>
		<collision>
			<origin xyz="0 0 0" />
			<geometry>
				<mesh filename="textured_objs/original-24.obj" />
			</geometry>
		</collision>
		<collision>
			<origin xyz="0 0 0" />
			<geometry>
				<mesh filename="textured_objs/original-20.obj" />
			</geometry>
		</collision>
		<collision>
			<origin xyz="0 0 0" />
			<geometry>
				<mesh filename="textured_objs/original-14.obj" />
			</geometry>
		</collision>
	<inertial><mass value="10" /><inertia ixx="1" ixy="0" ixz="0" iyy="1" iyz="0" izz="1" /></inertial></link>
	<joint name="joint_1" type="fixed">
		<origin rpy="1.570796326794897 0 -1.570796326794897" xyz="0 0 0" />
		<child link="link_1" />
		<parent link="base" />
	</joint>
</robot>