<robot name="partnet_2df413de74de82d2fcbd07bde5deede4">
	<link name="base"><inertial><mass value="10" /><inertia ixx="1" ixy="0" ixz="0" iyy="1" iyz="0" izz="1" /></inertial></link>
	<link name="link_0">
		<visual name="outside_frame-1">
			<origin xyz="0 0 0" />
			<geometry>
				<mesh filename="textured_objs/new-2.obj" />
			</geometry>
		</visual>
		<visual name="outside_frame-1">
			<origin xyz="0 0 0" />
			<geometry>
				<mesh filename="textured_objs/original-1.obj" />
			</geometry>
		</visual>
		<visual name="outside_frame-1">
			<origin xyz="0 0 0" />
			<geometry>
				<mesh filename="textured_objs/new-5.obj" />
			</geometry>
		</visual>
		<collision>
			<origin xyz="0 0 0" />
			<geometry>
				<mesh filename="textured_objs/new-2.obj" />
			</geometry>
		</collision>
		<collision>
			<origin xyz="0 0 0" />
			<geometry>
				<mesh filename="textured_objs/original-1.obj" />
			</geometry>
		</collision>
		<collision>
			<origin xyz="0 0 0" />
			<geometry>
				<mesh filename="textured_objs/new-5.obj" />
			</geometry>
		</collision>
	<inertial><mass value="10" /><inertia ixx="1" ixy="0" ixz="0" iyy="1" iyz="0" izz="1" /></inertial></link>
	<joint name="joint_0" type="fixed">
		<origin rpy="1.570796326794897 0 -1.570796326794897" xyz="0 0 0" />
		<child link="link_0" />
		<parent link="base" />
	</joint>
	<link name="link_1">
		<visual name="surface_board-12">
			<origin xyz="0.3432525537649009 -0.828824 0.004683688059689217" />
			<geometry>
				<mesh filename="textured_objs/new-3.obj" />
			</geometry>
		</visual>
		<visual name="surface_board-12">
			<origin xyz="0.3432525537649009 -0.828824 0.004683688059689217" />
			<geometry>
				<mesh filename="textured_objs/new-4.obj" />
			</geometry>
		</visual>
		<visual name="surface_board-12">
			<origin xyz="0.3432525537649009 -0.828824 0.004683688059689217" />
			<geometry>
				<mesh filename="textured_objs/new-0.obj" />
			</geometry>
		</visual>
		<visual name="surface_board-12">
			<origin xyz="0.3432525537649009 -0.828824 0.004683688059689217" />
			<geometry>
				<mesh filename="textured_objs/new-1.obj" />
			</geometry>
		</visual>
		<visual name="fixed_part-10">
			<origin xyz="0.3432525537649009 -0.828824 0.004683688059689217" />
			<geometry>
				<mesh filename="textured_objs/original-17.obj" />
			</geometry>
		</visual>
		<visual name="fixed_part-10">
			<origin xyz="0.3432525537649009 -0.828824 0.004683688059689217" />
			<geometry>
				<mesh filename="textured_objs/original-16.obj" />
			</geometry>
		</visual>
		<visual name="fixed_part-10">
			<origin xyz="0.3432525537649009 -0.828824 0.004683688059689217" />
			<geometry>
				<mesh filename="textured_objs/original-21.obj" />
			</geometry>
		</visual>
		<visual name="other_leaf-14">
			<origin xyz="0.3432525537649009 -0.828824 0.004683688059689217" />
			<geometry>
				<mesh filename="textured_objs/original-20.obj" />
			</geometry>
		</visual>
		<visual name="other_leaf-14">
			<origin xyz="0.3432525537649009 -0.828824 0.004683688059689217" />
			<geometry>
				<mesh filename="textured_objs/original-22.obj" />
			</geometry>
		</visual>
		<visual name="fixed_part-8">
			<origin xyz="0.3432525537649009 -0.828824 0.004683688059689217" />
			<geometry>
				<mesh filename="textured_objs/original-6.obj" />
			</geometry>
		</visual>
		<visual name="fixed_part-8">
			<origin xyz="0.3432525537649009 -0.828824 0.004683688059689217" />
			<geometry>
				<mesh filename="textured_objs/original-5.obj" />
			</geometry>
		</visual>
		<visual name="fixed_part-8">
			<origin xyz="0.3432525537649009 -0.828824 0.004683688059689217" />
			<geometry>
				<mesh filename="textured_objs/original-10.obj" />
			</geometry>
		</visual>
		<visual name="other_leaf-16">
			<origin xyz="0.3432525537649009 -0.828824 0.004683688059689217" />
			<geometry>
				<mesh filename="textured_objs/original-11.obj" />
			</geometry>
		</visual>
		<visual name="other_leaf-16">
			<origin xyz="0.3432525537649009 -0.828824 0.004683688059689217" />
			<geometry>
				<mesh filename="textured_objs/original-9.obj" />
			</geometry>
		</visual>
		<collision>
			<origin xyz="0.3432525537649009 -0.828824 0.004683688059689217" />
			<geometry>
				<mesh filename="textured_objs/new-3.obj" />
			</geometry>
		</collision>
		<collision>
			<origin xyz="0.3432525537649009 -0.828824 0.004683688059689217" />
			<geometry>
				<mesh filename="textured_objs/new-4.obj" />
			</geometry>
		</collision>
		<collision>
			<origin xyz="0.3432525537649009 -0.828824 0.004683688059689217" />
			<geometry>
				<mesh filename="textured_objs/new-0.obj" />
			</geometry>
		</collision>
		<collision>
			<origin xyz="0.3432525537649009 -0.828824 0.004683688059689217" />
			<geometry>
				<mesh filename="textured_objs/new-1.obj" />
			</geometry>
		</collision>
		<collision>
			<origin xyz="0.3432525537649009 -0.828824 0.004683688059689217" />
			<geometry>
				<mesh filename="textured_objs/original-17.obj" />
			</geometry>
		</collision>
		<collision>
			<origin xyz="0.3432525537649009 -0.828824 0.004683688059689217" />
			<geometry>
				<mesh filename="textured_objs/original-16.obj" />
			</geometry>
		</collision>
		<collision>
			<origin xyz="0.3432525537649009 -0.828824 0.004683688059689217" />
			<geometry>
				<mesh filename="textured_objs/original-21.obj" />
			</geometry>
		</collision>
		<collision>
			<origin xyz="0.3432525537649009 -0.828824 0.004683688059689217" />
			<geometry>
				<mesh filename="textured_objs/original-20.obj" />
			</geometry>
		</collision>
		<collision>
			<origin xyz="0.3432525537649009 -0.828824 0.004683688059689217" />
			<geometry>
				<mesh filename="textured_objs/original-22.obj" />
			</geometry>
		</collision>
		<collision>
			<origin xyz="0.3432525537649009 -0.828824 0.004683688059689217" />
			<geometry>
				<mesh filename="textured_objs/original-6.obj" />
			</geometry>
		</collision>
		<collision>
			<origin xyz="0.3432525537649009 -0.828824 0.004683688059689217" />
			<geometry>
				<mesh filename="textured_objs/original-5.obj" />
			</geometry>
		</collision>
		<collision>
			<origin xyz="0.3432525537649009 -0.828824 0.004683688059689217" />
			<geometry>
				<mesh filename="textured_objs/original-10.obj" />
			</geometry>
		</collision>
		<collision>
			<origin xyz="0.3432525537649009 -0.828824 0.004683688059689217" />
			<geometry>
				<mesh filename="textured_objs/original-11.obj" />
			</geometry>
		</collision>
		<collision>
			<origin xyz="0.3432525537649009 -0.828824 0.004683688059689217" />
			<geometry>
				<mesh filename="textured_objs/original-9.obj" />
			</geometry>
		</collision>
	<inertial><mass value="10" /><inertia ixx="1" ixy="0" ixz="0" iyy="1" iyz="0" izz="1" /></inertial></link>
	<joint name="joint_1" type="revolute">
		<origin xyz="-0.3432525537649009 0.828824 -0.004683688059689217" />
		<axis xyz="0 -1 0" />
		<child link="link_1" />
		<parent link="link_0" />
		<limit effort="30" lower="0.0" upper="1.5707963267948966" velocity="1.0" />
	</joint>
	<link name="link_2">
		<visual name="movable_part-11">
			<origin xyz="-0.27102619774442194 0.04494619130548938 -0.053442000000000434" />
			<geometry>
				<mesh filename="textured_objs/original-19.obj" />
			</geometry>
		</visual>
		<visual name="movable_part-11">
			<origin xyz="-0.27102619774442194 0.04494619130548938 -0.053442000000000434" />
			<geometry>
				<mesh filename="textured_objs/original-18.obj" />
			</geometry>
		</visual>
		<visual name="movable_part-9">
			<origin xyz="-0.27102619774442194 0.04494619130548938 -0.053442000000000434" />
			<geometry>
				<mesh filename="textured_objs/original-7.obj" />
			</geometry>
		</visual>
		<visual name="movable_part-9">
			<origin xyz="-0.27102619774442194 0.04494619130548938 -0.053442000000000434" />
			<geometry>
				<mesh filename="textured_objs/original-8.obj" />
			</geometry>
		</visual>
		<collision>
			<origin xyz="-0.27102619774442194 0.04494619130548938 -0.053442000000000434" />
			<geometry>
				<mesh filename="textured_objs/original-19.obj" />
			</geometry>
		</collision>
		<collision>
			<origin xyz="-0.27102619774442194 0.04494619130548938 -0.053442000000000434" />
			<geometry>
				<mesh filename="textured_objs/original-18.obj" />
			</geometry>
		</collision>
		<collision>
			<origin xyz="-0.27102619774442194 0.04494619130548938 -0.053442000000000434" />
			<geometry>
				<mesh filename="textured_objs/original-7.obj" />
			</geometry>
		</collision>
		<collision>
			<origin xyz="-0.27102619774442194 0.04494619130548938 -0.053442000000000434" />
			<geometry>
				<mesh filename="textured_objs/original-8.obj" />
			</geometry>
		</collision>
	<inertial><mass value="10" /><inertia ixx="1" ixy="0" ixz="0" iyy="1" iyz="0" izz="1" /></inertial></link>
	<joint name="joint_2" type="revolute">
		<origin xyz="0.6142787515093229 -0.8737701913054894 0.05812568805968965" />
		<axis xyz="0 0 1" />
		<child link="link_2" />
		<parent link="link_1" />
		<limit effort="30" lower="0.0" upper="1.5707963267948966" velocity="1.0" />
	</joint>
</robot>