<robot name="partnet_399cb702b96d2011dc5f68d8d7e8ab0">
	<link name="base"><inertial><mass value="10" /><inertia ixx="1" ixy="0" ixz="0" iyy="1" iyz="0" izz="1" /></inertial></link>
	<link name="link_0">
		<visual name="switch-1">
			<origin xyz="-0.8101530000000015 0.000755486902682824 -0.006919829480950812" />
			<geometry>
				<mesh filename="textured_objs/original-2.obj" />
			</geometry>
		</visual>
		<collision>
			<origin xyz="-0.8101530000000015 0.000755486902682824 -0.006919829480950812" />
			<geometry>
				<mesh filename="textured_objs/original-2.obj" />
			</geometry>
		</collision>
	<inertial><mass value="10" /><inertia ixx="1" ixy="0" ixz="0" iyy="1" iyz="0" izz="1" /></inertial></link>
	<joint name="joint_0" type="revolute">
		<origin xyz="0.8101530000000015 -0.000755486902682824 0.006919829480950812" />
		<axis xyz="-1 0 0" />
		<child link="link_0" />
		<parent link="link_2" />
		<limit effort="30" lower="-0.0" upper="0.15707963267948966" velocity="1.0" />
	</joint>
	<link name="link_1">
		<visual name="switch-2">
			<origin xyz="-0.8101530000000015 0.000755486902682824 -0.006919829480950812" />
			<geometry>
				<mesh filename="textured_objs/original-1.obj" />
			</geometry>
		</visual>
		<collision>
			<origin xyz="-0.8101530000000015 0.000755486902682824 -0.006919829480950812" />
			<geometry>
				<mesh filename="textured_objs/original-1.obj" />
			</geometry>
		</collision>
	<inertial><mass value="10" /><inertia ixx="1" ixy="0" ixz="0" iyy="1" iyz="0" izz="1" /></inertial></link>
	<joint name="joint_1" type="revolute">
		<origin xyz="0.8101530000000015 -0.000755486902682824 0.006919829480950812" />
		<axis xyz="-1 0 0" />
		<child link="link_1" />
		<parent link="link_2" />
		<limit effort="30" lower="-0.0" upper="0.15707963267948966" velocity="1.0" />
	</joint>
	<link name="link_2">
		<visual name="base_body-3">
			<origin xyz="0 0 0" />
			<geometry>
				<mesh filename="textured_objs/original-3.obj" />
			</geometry>
		</visual>
		<collision>
			<origin xyz="0 0 0" />
			<geometry>
				<mesh filename="textured_objs/original-3.obj" />
			</geometry>
		</collision>
	<inertial><mass value="10" /><inertia ixx="1" ixy="0" ixz="0" iyy="1" iyz="0" izz="1" /></inertial></link>
	<joint name="joint_2" type="fixed">
		<origin rpy="1.570796326794897 0 -1.570796326794897" xyz="0 0 0" />
		<child link="link_2" />
		<parent link="base" />
	</joint>
</robot>