<robot name="partnet_49600ad1eb1435d957f15fc9385a8a01">
	<link name="base"><inertial><mass value="10" /><inertia ixx="1" ixy="0" ixz="0" iyy="1" iyz="0" izz="1" /></inertial></link>
	<link name="link_0">
		<visual name="outside_frame-1">
			<origin xyz="0 0 0" />
			<geometry>
				<mesh filename="textured_objs/new-0.obj" />
			</geometry>
		</visual>
		<collision>
			<origin xyz="0 0 0" />
			<geometry>
				<mesh filename="textured_objs/new-0.obj" />
			</geometry>
		</collision>
	<inertial><mass value="10" /><inertia ixx="1" ixy="0" ixz="0" iyy="1" iyz="0" izz="1" /></inertial></link>
	<joint name="joint_0" type="fixed">
		<origin rpy="1.570796326794897 0 -1.570796326794897" xyz="0 0 0" />
		<child link="link_0" />
		<parent link="base" />
	</joint>
	<link name="link_1">
		<visual name="surface_board-7">
			<origin xyz="0.4284572085650428 -0.9016810000000004 -0.013949575438850337" />
			<geometry>
				<mesh filename="textured_objs/new-1.obj" />
			</geometry>
		</visual>
		<visual name="complex_decoration-8">
			<origin xyz="0.4284572085650428 -0.9016810000000004 -0.013949575438850337" />
			<geometry>
				<mesh filename="textured_objs/original-4.obj" />
			</geometry>
		</visual>
		<visual name="complex_decoration-9">
			<origin xyz="0.4284572085650428 -0.9016810000000004 -0.013949575438850337" />
			<geometry>
				<mesh filename="textured_objs/original-2.obj" />
			</geometry>
		</visual>
		<visual name="complex_decoration-10">
			<origin xyz="0.4284572085650428 -0.9016810000000004 -0.013949575438850337" />
			<geometry>
				<mesh filename="textured_objs/original-3.obj" />
			</geometry>
		</visual>
		<collision>
			<origin xyz="0.4284572085650428 -0.9016810000000004 -0.013949575438850337" />
			<geometry>
				<mesh filename="textured_objs/new-1.obj" />
			</geometry>
		</collision>
		<collision>
			<origin xyz="0.4284572085650428 -0.9016810000000004 -0.013949575438850337" />
			<geometry>
				<mesh filename="textured_objs/original-4.obj" />
			</geometry>
		</collision>
		<collision>
			<origin xyz="0.4284572085650428 -0.9016810000000004 -0.013949575438850337" />
			<geometry>
				<mesh filename="textured_objs/original-2.obj" />
			</geometry>
		</collision>
		<collision>
			<origin xyz="0.4284572085650428 -0.9016810000000004 -0.013949575438850337" />
			<geometry>
				<mesh filename="textured_objs/original-3.obj" />
			</geometry>
		</collision>
	<inertial><mass value="10" /><inertia ixx="1" ixy="0" ixz="0" iyy="1" iyz="0" izz="1" /></inertial></link>
	<joint name="joint_1" type="revolute">
		<origin xyz="-0.4284572085650428 0.9016810000000004 0.013949575438850337" />
		<axis xyz="0 -1 0" />
		<child link="link_1" />
		<parent link="link_0" />
		<limit effort="30" lower="0.0" upper="1.5707963267948966" velocity="1.0" />
	</joint>
	<link name="link_2">
		<visual name="fixed_part-5">
			<origin xyz="-0.33759700000000004 0.1109 0" />
			<geometry>
				<mesh filename="textured_objs/original-1.obj" />
			</geometry>
		</visual>
		<visual name="fixed_part-6">
			<origin xyz="-0.33759700000000004 0.1109 0" />
			<geometry>
				<mesh filename="textured_objs/original-5.obj" />
			</geometry>
		</visual>
		<collision>
			<origin xyz="-0.33759700000000004 0.1109 0" />
			<geometry>
				<mesh filename="textured_objs/original-1.obj" />
			</geometry>
		</collision>
		<collision>
			<origin xyz="-0.33759700000000004 0.1109 0" />
			<geometry>
				<mesh filename="textured_objs/original-5.obj" />
			</geometry>
		</collision>
	<inertial><mass value="10" /><inertia ixx="1" ixy="0" ixz="0" iyy="1" iyz="0" izz="1" /></inertial></link>
	<joint name="joint_2" type="revolute">
		<origin xyz="0.7660542085650428 -1.0125810000000004 -0.013949575438850337" />
		<axis xyz="0 0 -1" />
		<child link="link_2" />
		<parent link="link_1" />
		<limit effort="30" lower="-0.0" upper="1.5707963267948966" velocity="1.0" />
	</joint>
</robot>