<robot name="partnet_1db67269a35f5e223df325aac2f73830">
	<link name="base"><inertial><mass value="10" /><inertia ixx="1" ixy="0" ixz="0" iyy="1" iyz="0" izz="1" /></inertial></link>
	<link name="link_0">
		<visual name="outside_frame-9">
			<origin xyz="0 0 0" />
			<geometry>
				<mesh filename="textured_objs/new-6.obj" />
			</geometry>
		</visual>
		<collision>
			<origin xyz="0 0 0" />
			<geometry>
				<mesh filename="textured_objs/new-6.obj" />
			</geometry>
		</collision>
	<inertial><mass value="10" /><inertia ixx="1" ixy="0" ixz="0" iyy="1" iyz="0" izz="1" /></inertial></link>
	<joint name="joint_0" type="fixed">
		<origin rpy="1.570796326794897 0 -1.570796326794897" xyz="0 0 0" />
		<child link="link_0" />
		<parent link="base" />
	</joint>
	<link name="link_1">
		<visual name="surface_board-10">
			<origin xyz="0.40236311158768856 -0.8432179999999994 0.0035260027887758505" />
			<geometry>
				<mesh filename="textured_objs/new-5.obj" />
			</geometry>
		</visual>
		<visual name="surface_board-10">
			<origin xyz="0.40236311158768856 -0.8432179999999994 0.0035260027887758505" />
			<geometry>
				<mesh filename="textured_objs/new-4.obj" />
			</geometry>
		</visual>
		<visual name="other_leaf-8">
			<origin xyz="0.40236311158768856 -0.8432179999999994 0.0035260027887758505" />
			<geometry>
				<mesh filename="textured_objs/new-3.obj" />
			</geometry>
		</visual>
		<visual name="other_leaf-8">
			<origin xyz="0.40236311158768856 -0.8432179999999994 0.0035260027887758505" />
			<geometry>
				<mesh filename="textured_objs/new-0.obj" />
			</geometry>
		</visual>
		<visual name="other_leaf-7">
			<origin xyz="0.40236311158768856 -0.8432179999999994 0.0035260027887758505" />
			<geometry>
				<mesh filename="textured_objs/new-1.obj" />
			</geometry>
		</visual>
		<visual name="other_leaf-7">
			<origin xyz="0.40236311158768856 -0.8432179999999994 0.0035260027887758505" />
			<geometry>
				<mesh filename="textured_objs/new-2.obj" />
			</geometry>
		</visual>
		<collision>
			<origin xyz="0.40236311158768856 -0.8432179999999994 0.0035260027887758505" />
			<geometry>
				<mesh filename="textured_objs/new-5.obj" />
			</geometry>
		</collision>
		<collision>
			<origin xyz="0.40236311158768856 -0.8432179999999994 0.0035260027887758505" />
			<geometry>
				<mesh filename="textured_objs/new-4.obj" />
			</geometry>
		</collision>
		<collision>
			<origin xyz="0.40236311158768856 -0.8432179999999994 0.0035260027887758505" />
			<geometry>
				<mesh filename="textured_objs/new-3.obj" />
			</geometry>
		</collision>
		<collision>
			<origin xyz="0.40236311158768856 -0.8432179999999994 0.0035260027887758505" />
			<geometry>
				<mesh filename="textured_objs/new-0.obj" />
			</geometry>
		</collision>
		<collision>
			<origin xyz="0.40236311158768856 -0.8432179999999994 0.0035260027887758505" />
			<geometry>
				<mesh filename="textured_objs/new-1.obj" />
			</geometry>
		</collision>
		<collision>
			<origin xyz="0.40236311158768856 -0.8432179999999994 0.0035260027887758505" />
			<geometry>
				<mesh filename="textured_objs/new-2.obj" />
			</geometry>
		</collision>
	<inertial><mass value="10" /><inertia ixx="1" ixy="0" ixz="0" iyy="1" iyz="0" izz="1" /></inertial></link>
	<joint name="joint_1" type="revolute">
		<origin xyz="-0.40236311158768856 0.8432179999999994 -0.0035260027887758505" />
		<axis xyz="0 -1 0" />
		<child link="link_1" />
		<parent link="link_0" />
		<limit effort="30" lower="0.0" upper="1.5707963267948966" velocity="1.0" />
	</joint>
</robot>