<robot name="partnet_5ac537b47ccd0f15c5924a1a5d3043b0">
	<link name="base"><inertial><mass value="10" /><inertia ixx="1" ixy="0" ixz="0" iyy="1" iyz="0" izz="1" /></inertial></link>
	<link name="link_0">
		<visual name="outside_frame-1">
			<origin xyz="0 0 0" />
			<geometry>
				<mesh filename="textured_objs/original-6.obj" />
			</geometry>
		</visual>
		<visual name="outside_frame-1">
			<origin xyz="0 0 0" />
			<geometry>
				<mesh filename="textured_objs/original-11.obj" />
			</geometry>
		</visual>
		<visual name="outside_frame-1">
			<origin xyz="0 0 0" />
			<geometry>
				<mesh filename="textured_objs/original-7.obj" />
			</geometry>
		</visual>
		<visual name="outside_frame-1">
			<origin xyz="0 0 0" />
			<geometry>
				<mesh filename="textured_objs/original-2.obj" />
			</geometry>
		</visual>
		<visual name="outside_frame-1">
			<origin xyz="0 0 0" />
			<geometry>
				<mesh filename="textured_objs/original-12.obj" />
			</geometry>
		</visual>
		<visual name="outside_frame-1">
			<origin xyz="0 0 0" />
			<geometry>
				<mesh filename="textured_objs/original-9.obj" />
			</geometry>
		</visual>
		<visual name="outside_frame-1">
			<origin xyz="0 0 0" />
			<geometry>
				<mesh filename="textured_objs/original-8.obj" />
			</geometry>
		</visual>
		<visual name="outside_frame-1">
			<origin xyz="0 0 0" />
			<geometry>
				<mesh filename="textured_objs/original-10.obj" />
			</geometry>
		</visual>
		<collision>
			<origin xyz="0 0 0" />
			<geometry>
				<mesh filename="textured_objs/original-6.obj" />
			</geometry>
		</collision>
		<collision>
			<origin xyz="0 0 0" />
			<geometry>
				<mesh filename="textured_objs/original-11.obj" />
			</geometry>
		</collision>
		<collision>
			<origin xyz="0 0 0" />
			<geometry>
				<mesh filename="textured_objs/original-7.obj" />
			</geometry>
		</collision>
		<collision>
			<origin xyz="0 0 0" />
			<geometry>
				<mesh filename="textured_objs/original-2.obj" />
			</geometry>
		</collision>
		<collision>
			<origin xyz="0 0 0" />
			<geometry>
				<mesh filename="textured_objs/original-12.obj" />
			</geometry>
		</collision>
		<collision>
			<origin xyz="0 0 0" />
			<geometry>
				<mesh filename="textured_objs/original-9.obj" />
			</geometry>
		</collision>
		<collision>
			<origin xyz="0 0 0" />
			<geometry>
				<mesh filename="textured_objs/original-8.obj" />
			</geometry>
		</collision>
		<collision>
			<origin xyz="0 0 0" />
			<geometry>
				<mesh filename="textured_objs/original-10.obj" />
			</geometry>
		</collision>
	<inertial><mass value="10" /><inertia ixx="1" ixy="0" ixz="0" iyy="1" iyz="0" izz="1" /></inertial></link>
	<joint name="joint_0" type="fixed">
		<origin rpy="1.570796326794897 0 -1.570796326794897" xyz="0 0 0" />
		<child link="link_0" />
		<parent link="base" />
	</joint>
	<link name="link_1">
		<visual name="surface_board-22">
			<origin xyz="0.12825737327838105 -0.7112019999999997 0.2131384352424056" />
			<geometry>
				<mesh filename="textured_objs/original-1.obj" />
			</geometry>
		</visual>
		<visual name="other_leaf-17">
			<origin xyz="0.12825737327838105 -0.7112019999999997 0.2131384352424056" />
			<geometry>
				<mesh filename="textured_objs/original-5.obj" />
			</geometry>
		</visual>
		<visual name="other_leaf-17">
			<origin xyz="0.12825737327838105 -0.7112019999999997 0.2131384352424056" />
			<geometry>
				<mesh filename="textured_objs/original-3.obj" />
			</geometry>
		</visual>
		<visual name="fixed_part-20">
			<origin xyz="0.12825737327838105 -0.7112019999999997 0.2131384352424056" />
			<geometry>
				<mesh filename="textured_objs/original-20.obj" />
			</geometry>
		</visual>
		<visual name="fixed_part-18">
			<origin xyz="0.12825737327838105 -0.7112019999999997 0.2131384352424056" />
			<geometry>
				<mesh filename="textured_objs/original-15.obj" />
			</geometry>
		</visual>
		<collision>
			<origin xyz="0.12825737327838105 -0.7112019999999997 0.2131384352424056" />
			<geometry>
				<mesh filename="textured_objs/original-1.obj" />
			</geometry>
		</collision>
		<collision>
			<origin xyz="0.12825737327838105 -0.7112019999999997 0.2131384352424056" />
			<geometry>
				<mesh filename="textured_objs/original-5.obj" />
			</geometry>
		</collision>
		<collision>
			<origin xyz="0.12825737327838105 -0.7112019999999997 0.2131384352424056" />
			<geometry>
				<mesh filename="textured_objs/original-3.obj" />
			</geometry>
		</collision>
		<collision>
			<origin xyz="0.12825737327838105 -0.7112019999999997 0.2131384352424056" />
			<geometry>
				<mesh filename="textured_objs/original-20.obj" />
			</geometry>
		</collision>
		<collision>
			<origin xyz="0.12825737327838105 -0.7112019999999997 0.2131384352424056" />
			<geometry>
				<mesh filename="textured_objs/original-15.obj" />
			</geometry>
		</collision>
	<inertial><mass value="10" /><inertia ixx="1" ixy="0" ixz="0" iyy="1" iyz="0" izz="1" /></inertial></link>
	<joint name="joint_1" type="revolute">
		<origin xyz="-0.12825737327838105 0.7112019999999997 -0.2131384352424056" />
		<axis xyz="0 -1 0" />
		<child link="link_1" />
		<parent link="link_0" />
		<limit effort="30" lower="-1.5707963267948966" upper="-0.0" velocity="1.0" />
	</joint>
	<link name="link_2">
		<visual name="movable_part-21">
			<origin xyz="0.17871300000000034 0.1399846628750067 -0.39987489142255717" />
			<geometry>
				<mesh filename="textured_objs/original-19.obj" />
			</geometry>
		</visual>
		<visual name="movable_part-21">
			<origin xyz="0.17871300000000034 0.1399846628750067 -0.39987489142255717" />
			<geometry>
				<mesh filename="textured_objs/original-22.obj" />
			</geometry>
		</visual>
		<visual name="movable_part-21">
			<origin xyz="0.17871300000000034 0.1399846628750067 -0.39987489142255717" />
			<geometry>
				<mesh filename="textured_objs/original-21.obj" />
			</geometry>
		</visual>
		<visual name="movable_part-19">
			<origin xyz="0.17871300000000034 0.1399846628750067 -0.39987489142255717" />
			<geometry>
				<mesh filename="textured_objs/original-16.obj" />
			</geometry>
		</visual>
		<visual name="movable_part-19">
			<origin xyz="0.17871300000000034 0.1399846628750067 -0.39987489142255717" />
			<geometry>
				<mesh filename="textured_objs/original-17.obj" />
			</geometry>
		</visual>
		<visual name="movable_part-19">
			<origin xyz="0.17871300000000034 0.1399846628750067 -0.39987489142255717" />
			<geometry>
				<mesh filename="textured_objs/original-14.obj" />
			</geometry>
		</visual>
		<collision>
			<origin xyz="0.17871300000000034 0.1399846628750067 -0.39987489142255717" />
			<geometry>
				<mesh filename="textured_objs/original-19.obj" />
			</geometry>
		</collision>
		<collision>
			<origin xyz="0.17871300000000034 0.1399846628750067 -0.39987489142255717" />
			<geometry>
				<mesh filename="textured_objs/original-22.obj" />
			</geometry>
		</collision>
		<collision>
			<origin xyz="0.17871300000000034 0.1399846628750067 -0.39987489142255717" />
			<geometry>
				<mesh filename="textured_objs/original-21.obj" />
			</geometry>
		</collision>
		<collision>
			<origin xyz="0.17871300000000034 0.1399846628750067 -0.39987489142255717" />
			<geometry>
				<mesh filename="textured_objs/original-16.obj" />
			</geometry>
		</collision>
		<collision>
			<origin xyz="0.17871300000000034 0.1399846628750067 -0.39987489142255717" />
			<geometry>
				<mesh filename="textured_objs/original-17.obj" />
			</geometry>
		</collision>
		<collision>
			<origin xyz="0.17871300000000034 0.1399846628750067 -0.39987489142255717" />
			<geometry>
				<mesh filename="textured_objs/original-14.obj" />
			</geometry>
		</collision>
	<inertial><mass value="10" /><inertia ixx="1" ixy="0" ixz="0" iyy="1" iyz="0" izz="1" /></inertial></link>
	<joint name="joint_2" type="revolute">
		<origin xyz="-0.050455626721619296 -0.8511866628750063 0.6130133266649628" />
		<axis xyz="1 0 0" />
		<child link="link_2" />
		<parent link="link_1" />
		<limit effort="30" lower="0.0" upper="0.0" velocity="1.0" />
	</joint>
</robot>