<robot name="partnet_bf22375c9e333ae91d4b46ed3c9112e1">
	<link name="base"><inertial><mass value="10" /><inertia ixx="1" ixy="0" ixz="0" iyy="1" iyz="0" izz="1" /></inertial></link>
	<link name="link_0">
		<visual name="outside_frame-1">
			<origin xyz="0 0 0" />
			<geometry>
				<mesh filename="textured_objs/original-6.obj" />
			</geometry>
		</visual>
		<visual name="outside_frame-1">
			<origin xyz="0 0 0" />
			<geometry>
				<mesh filename="textured_objs/original-7.obj" />
			</geometry>
		</visual>
		<collision>
			<origin xyz="0 0 0" />
			<geometry>
				<mesh filename="textured_objs/original-6.obj" />
			</geometry>
		</collision>
		<collision>
			<origin xyz="0 0 0" />
			<geometry>
				<mesh filename="textured_objs/original-7.obj" />
			</geometry>
		</collision>
	<inertial><mass value="10" /><inertia ixx="1" ixy="0" ixz="0" iyy="1" iyz="0" izz="1" /></inertial></link>
	<joint name="joint_0" type="fixed">
		<origin rpy="1.570796326794897 0 -1.570796326794897" xyz="0 0 0" />
		<child link="link_0" />
		<parent link="base" />
	</joint>
	<link name="link_1">
		<visual name="fixed_part-5">
			<origin xyz="0.31675829671810396 0.07280867447711076 -0.08675934455818946" />
			<geometry>
				<mesh filename="textured_objs/original-4.obj" />
			</geometry>
		</visual>
		<collision>
			<origin xyz="0.31675829671810396 0.07280867447711076 -0.08675934455818946" />
			<geometry>
				<mesh filename="textured_objs/original-4.obj" />
			</geometry>
		</collision>
	<inertial><mass value="10" /><inertia ixx="1" ixy="0" ixz="0" iyy="1" iyz="0" izz="1" /></inertial></link>
	<joint name="joint_1" type="continuous">
		<origin xyz="-0.6692401893420089 -0.9877126744771108 0.09123124574349506" />
		<axis xyz="0 0 1" />
		<child link="link_1" />
		<parent link="link_2" />
	</joint>
	<link name="link_2">
		<visual name="surface_board-6">
			<origin xyz="-0.35248189262390495 -0.9149039999999999 0.0044719011853056045" />
			<geometry>
				<mesh filename="textured_objs/original-2.obj" />
			</geometry>
		</visual>
		<visual name="surface_board-6">
			<origin xyz="-0.35248189262390495 -0.9149039999999999 0.0044719011853056045" />
			<geometry>
				<mesh filename="textured_objs/original-3.obj" />
			</geometry>
		</visual>
		<visual name="glass-7">
			<origin xyz="-0.35248189262390495 -0.9149039999999999 0.0044719011853056045" />
			<geometry>
				<mesh filename="textured_objs/original-8.obj" />
			</geometry>
		</visual>
		<collision>
			<origin xyz="-0.35248189262390495 -0.9149039999999999 0.0044719011853056045" />
			<geometry>
				<mesh filename="textured_objs/original-2.obj" />
			</geometry>
		</collision>
		<collision>
			<origin xyz="-0.35248189262390495 -0.9149039999999999 0.0044719011853056045" />
			<geometry>
				<mesh filename="textured_objs/original-3.obj" />
			</geometry>
		</collision>
		<collision>
			<origin xyz="-0.35248189262390495 -0.9149039999999999 0.0044719011853056045" />
			<geometry>
				<mesh filename="textured_objs/original-8.obj" />
			</geometry>
		</collision>
	<inertial><mass value="10" /><inertia ixx="1" ixy="0" ixz="0" iyy="1" iyz="0" izz="1" /></inertial></link>
	<joint name="joint_2" type="revolute">
		<origin xyz="0.35248189262390495 0.9149039999999999 -0.0044719011853056045" />
		<axis xyz="0 -1 0" />
		<child link="link_2" />
		<parent link="link_0" />
		<limit effort="30" lower="0.0" upper="1.5707963267948966" velocity="1.0" />
	</joint>
</robot>