<robot name="partnet_eaee5eb38124c72e1a45d531656bc96d">
	<link name="base"><inertial><mass value="10" /><inertia ixx="1" ixy="0" ixz="0" iyy="1" iyz="0" izz="1" /></inertial></link>
	<link name="link_0">
		<visual name="switch-1">
			<origin xyz="0 0.006390567813209253 -0.05" />
			<geometry>
				<mesh filename="textured_objs/original-2.obj" />
			</geometry>
		</visual>
		<visual name="switch-1">
			<origin xyz="0 0.006390567813209253 -0.05" />
			<geometry>
				<mesh filename="textured_objs/original-8.obj" />
			</geometry>
		</visual>
		<collision>
			<origin xyz="0 0.006390567813209253 -0.05" />
			<geometry>
				<mesh filename="textured_objs/original-2.obj" />
			</geometry>
		</collision>
		<collision>
			<origin xyz="0 0.006390567813209253 -0.05" />
			<geometry>
				<mesh filename="textured_objs/original-8.obj" />
			</geometry>
		</collision>
	<inertial><mass value="10" /><inertia ixx="1" ixy="0" ixz="0" iyy="1" iyz="0" izz="1" /></inertial></link>
	<joint name="joint_0" type="revolute">
		<origin xyz="0 -0.006390567813209253 0.05" />
		<axis xyz="1 0 0" />
		<child link="link_0" />
		<parent link="link_3" />
		<limit effort="30" lower="0.0" upper="0.41887902047863906" velocity="1.0" />
	</joint>
	<link name="link_1">
		<visual name="switch-2">
			<origin xyz="0 0.006390567813209253 -0.05" />
			<geometry>
				<mesh filename="textured_objs/original-6.obj" />
			</geometry>
		</visual>
		<visual name="switch-2">
			<origin xyz="0 0.006390567813209253 -0.05" />
			<geometry>
				<mesh filename="textured_objs/original-9.obj" />
			</geometry>
		</visual>
		<collision>
			<origin xyz="0 0.006390567813209253 -0.05" />
			<geometry>
				<mesh filename="textured_objs/original-6.obj" />
			</geometry>
		</collision>
		<collision>
			<origin xyz="0 0.006390567813209253 -0.05" />
			<geometry>
				<mesh filename="textured_objs/original-9.obj" />
			</geometry>
		</collision>
	<inertial><mass value="10" /><inertia ixx="1" ixy="0" ixz="0" iyy="1" iyz="0" izz="1" /></inertial></link>
	<joint name="joint_1" type="revolute">
		<origin xyz="0 -0.006390567813209253 0.05" />
		<axis xyz="1 0 0" />
		<child link="link_1" />
		<parent link="link_3" />
		<limit effort="30" lower="0.0" upper="0.41887902047863906" velocity="1.0" />
	</joint>
	<link name="link_2">
		<visual name="switch-3">
			<origin xyz="0 0.006390567813209253 -0.05" />
			<geometry>
				<mesh filename="textured_objs/original-7.obj" />
			</geometry>
		</visual>
		<visual name="switch-3">
			<origin xyz="0 0.006390567813209253 -0.05" />
			<geometry>
				<mesh filename="textured_objs/original-4.obj" />
			</geometry>
		</visual>
		<collision>
			<origin xyz="0 0.006390567813209253 -0.05" />
			<geometry>
				<mesh filename="textured_objs/original-7.obj" />
			</geometry>
		</collision>
		<collision>
			<origin xyz="0 0.006390567813209253 -0.05" />
			<geometry>
				<mesh filename="textured_objs/original-4.obj" />
			</geometry>
		</collision>
	<inertial><mass value="10" /><inertia ixx="1" ixy="0" ixz="0" iyy="1" iyz="0" izz="1" /></inertial></link>
	<joint name="joint_2" type="revolute">
		<origin xyz="0 -0.006390567813209253 0.05" />
		<axis xyz="1 0 0" />
		<child link="link_2" />
		<parent link="link_3" />
		<limit effort="30" lower="0.0" upper="0.41887902047863906" velocity="1.0" />
	</joint>
	<link name="link_3">
		<visual name="base_body-4">
			<origin xyz="0 0 0" />
			<geometry>
				<mesh filename="textured_objs/original-3.obj" />
			</geometry>
		</visual>
		<visual name="base_body-4">
			<origin xyz="0 0 0" />
			<geometry>
				<mesh filename="textured_objs/original-5.obj" />
			</geometry>
		</visual>
		<visual name="base_body-4">
			<origin xyz="0 0 0" />
			<geometry>
				<mesh filename="textured_objs/original-1.obj" />
			</geometry>
		</visual>
		<collision>
			<origin xyz="0 0 0" />
			<geometry>
				<mesh filename="textured_objs/original-3.obj" />
			</geometry>
		</collision>
		<collision>
			<origin xyz="0 0 0" />
			<geometry>
				<mesh filename="textured_objs/original-5.obj" />
			</geometry>
		</collision>
		<collision>
			<origin xyz="0 0 0" />
			<geometry>
				<mesh filename="textured_objs/original-1.obj" />
			</geometry>
		</collision>
	<inertial><mass value="10" /><inertia ixx="1" ixy="0" ixz="0" iyy="1" iyz="0" izz="1" /></inertial></link>
	<joint name="joint_3" type="fixed">
		<origin rpy="1.570796326794897 0 -1.570796326794897" xyz="0 0 0" />
		<child link="link_3" />
		<parent link="base" />
	</joint>
</robot>